Workbook

Sheet StatusReport_2026_NovaFormula
A1: Project ID | B1: Project Name | C1: Status Projeto | D1: Responsável pelo Envio | E1: Semana 1 | F1: Semana 2 | G1: Semana 3 | H1: Semana 4 | I1: Semana 5 | J1: Semana 6 | K1: Semana 7 | L1: Semana 8 | M1: Semana 9 | N1: Semana 10 | O1: Semana 11 | P1: Semana 12 | Q1: Semana 13 | R1: Semana 14 | S1: Semana 15 | T1: Semana 16 | U1: Semana 17 | V1: Semana 18 | W1: Semana 19 | X1: Semana 20 | Y1: Semana 21 | Z1: Semana 22 | AA1: Semana 23 | AB1: Semana 24 | AC1: Semana 25 | AD1: Semana 26 | AE1: Semana 27 | AF1: Semana 28 | AG1: Semana 29 | AH1: Semana 30 | AI1: Semana 31 | AJ1: Semana 32 | AK1: Semana 33 | AL1: Semana 34 | AM1: Semana 35 | AN1: Semana 36 | AO1: Semana 37 | AP1: Semana 38 | AQ1: Semana 39 | AR1: Semana 40 | AS1: Semana 41 | AT1: Semana 42 | AU1: Semana 43 | AV1: Semana 44 | AW1: Semana 45 | AX1: Semana 46 | AY1: Semana 47 | AZ1: Semana 48 | BA1: Semana 49 | BB1: Semana 50 | BC1: Semana 51 | BD1: Semana 52 | BE1: Total de Status nas Semanas | BF1: Total de status não enviados | BG1: Total que deveria ter sido enviado | BH1: OBS | BI1: PM | BJ1: Detal. Resp. Envio
A2: PRJ0010317 | B2: ADN - Integração PI System x SysCAD _ 2025 | C2: ativo | E2: OK | BE2: 4 | BF2: 19 | BG2: 23 | BI2: Felipe Athar
A3: PRJ-3371 | B3: ADN24 - Migração do GPA para o ICS | C3: ativo | E3: OK | BI3: Felipe Athar
A4: PRJ-3413 | B4: ADN - SGA - Fase 03 | C4: on hold | E4: OK | BE4: 3 | BF4: 20 | BG4: 23 | BI4: Thamires Ribeiro
A5: PRJ-3509 | B5: ADN23 - SGE (Sistema de Gestão de Eventos) | C5: ativo | E5: OK | BE5: 5 | BF5: 18 | BG5: 23 | BI5: Felipe Athar
A6: PRJ-2539 | B6: ADN24 - Migração PI System para o ICS - Fase 1 | C6: concluído | E6: OK | BE6: 0 | BF6: 23 | BG6: 23 | BI6: Felipe Athar
A7: PRJ0010643 | B7: ADN25 - FC02 FIBRA MINERODUTO | C7: cancelado | E7: OK | BE7: 0 | BF7: 23 | BG7: 23 | BI7: Felipe Athar
A8: PRJ-3828 | B8: ADN25 - FC03 CONECTIVIDADE OPGW | C8: cancelado | E8: OK | BE8: 0 | BF8: 23 | BG8: 23 | BI8: Felipe Athar
A9: PRJ0010573 | B9: ADN25 - FC06 LTE | C9: on hold | E9: OK | BE9: 0 | BF9: 23 | BG9: 23 | BI9: Felipe Athar
A10: PRJ-3443 | B10: ADN25 - FC08 RÁDIO LINK | C10: on hold | E10: OK | BE10: 7 | BF10: 16 | BG10: 23 | BI10: Felipe Athar
A11: PRJ0010430 | B11: ADN25 - Migração do PI System para o ICS - Fase 02 | C11: ativo | E11: OK | BE11: 7 | BF11: 16 | BG11: 23 | BI11: Felipe Athar
A12: PRJ0010398 | B12: Expansion & Renovation Project | C12: ativo | E12: OK | BE12: 0 | BF12: 23 | BG12: 23 | BI12: Felipe Athar
A13: PRJ0010312 | B13: HOC - Hydro Operations Center | C13: ativo | E13: OK | BE13: 10 | BF13: 13 | BG13: 23 | BI13: Felipe Athar
A14: PRJ-1478 | B14: ICS Config ISE and WLC | C14: ativo | E14: OK | BE14: 6 | BF14: 17 | BG14: 23 | BI14: Felipe Athar
A15: PRJ0010397 | B15: Integração Starlink a WLAN controller | C15: concluído | E15: OK | BE15: 0 | BF15: 23 | BG15: 23 | BI15: Felipe Athar
... A17: PRJ0010574 | B17: PAM22 - FC05 LTE | C17: ativo | E17: OK | BE17: 17 | BF17: 6 | BG17: 23 | BI17: Felipe Athar
A18: PRJ0010716 | B18: PAM22 - Fibra Mina Cidade | C18: ativo | D18: julio.cesar.oliveira@hydro.com | E18: OK | BE18: 5 | BF18: 18 | BG18: 23 | BI18: Felipe Athar
A19: PRJ0010420 | B19: PAM22 - Monitoramento das Torres de Transmissão | C19: ativo | E19: OK | BE19: 2 | BF19: 21 | BG19: 23 | BI19: Thamires Ribeiro
A20: PRJ0010609 | B20: PAM24 - Ampliação da cobertura do sinal móvel | C20: ativo | E20: OK | BE20: 0 | BF20: 23 | BG20: 23 | BI20: Felipe Athar
A21: PRJ0010563 | B21: PAM24 - Gestão de Paradas de Ativos | C21: a iniciar | E21: OK | BE21: 2 | BF21: 21 | BG21: 23 | BI21: Thamires Ribeiro
A22: PRJ0010543 | B22: PAM24 - M5 - Corporate Networking | C22: on hold | E22: OK | BE22: 0 | BF22: 23 | BG22: 23 | BI22: Thamires Ribeiro
A23: PRJ0010541 | B23: PAM24 - M5 - Cabine Remota | C23: ativo | D23: julio.cesar.oliveira@hydro.com | E23: OK | BE23: 0 | BF23: 23 | BG23: 23 | BI23: Thamires Ribeiro
A24: PRJ0010532 | B24: PAM24 Topography Backup | C24: on hold | E24: OK | BE24: 0 | BF24: 23 | BG24: 23 | BI24: Felipe Athar
A25: PRJ-3821 | B25: PAM25 - Embuchamento dos Moinhos | C25: a iniciar | E25: OK | BE25: 0 | BF25: 23 | BG25: 23 | BI25: Thamires Ribeiro
A26: PRJ0010288 | B26: PAM25 - GEOTEC - Otimização de Disposição | C26: ativo | E26: OK | BE26: 11 | BF26: 12 | BG26: 23 | BI26: Thamires Ribeiro
A27: PRJ0010567 | B27: PAM25 - GEOTEC - Integração Rede Geotecnia | C27: ativo | E27: OK | BE27: 7 | BF27: 16 | BG27: 23 | BI27: Thamires Ribeiro
A28: PRJ0010144 | B28: PAM25 - GEOTEC - Verificação Anomalias IA | C28: ativo | E28: OK | BE28: 10 | BF28: 13 | BG28: 23 | BI28: Thamires Ribeiro
A29: PRJ-3468 | B29: PAM25 - GEOTEC - Visibilidade noturna | C29: ativo | E29: OK | BE29: 10 | BF29: 13 | BG29: 23 | BI29: Thamires Ribeiro
A30: PRJ0010223 | B30: PAM25 - GEOTEC - Monitoramento ZAS | C30: ativo | E30: OK | BF30: 23 | BI30: Thamires Ribeiro
A31: PRJ0010379 | B31: PAM25 - Migração Servidores Despacho | C31: ativo | D31: julio.cesar.oliveira@hydro.com | E31: OK | BE31: 8 | BF31: 15 | BG31: 23 | BI31: Thamires Ribeiro
A32: PRJ-3441 | B32: PAM25 - Process Optimization | C32: on hold | E32: OK | BE32: 0 | BF32: 23 | BG32: 23 | BI32: Thamires Ribeiro
A33: PRJ0010299 | B33: PAM25 - Otimização Consumo Floculante | C33: on hold | E33: OK | BE33: 2.5 | BF33: 20.5 | BG33: 23 | BI33: Thamires Ribeiro
A34: PRJ0010399 | B34: PAM25 FPS02 Governança PI System | C34: ativo | E34: OK | BE34: 5 | BF34: 18 | BG34: 23 | BI34: Felipe Athar
A35: PRJ0010322 | B35: PAM25 PO01 Controle Regulatório Ciclonagem | C35: ativo | E35: OK | BE35: 6 | BF35: 17 | BG35: 23 | BI35: Thamires Ribeiro
A36: PRJ0010715 | B36: PAM26 - Ampliação do CFTV da MPSA | C36: ativo | E36: OK | BE36: 12 | BF36: 11 | BG36: 23 | BI36: Thamires Ribeiro
A37: PRJ0010558 | B37: PAM26 - Câmeras Corporais | C37: ativo | E37: OK | BE37: 1 | BF37: 22 | BG37: 23 | BI37: Thamires Ribeiro
A38: PRJ0010259 | B38: PoC AVEVA Mobile Operator | C38: on hold | E38: OK | BE38: 0 | BF38: 23 | BG38: 23 | BI38: Thamires Ribeiro
A39: PRJ0010258 | B39: Programa Ecoar | C39: ativo | D39: julio.cesar.oliveira@hydro.com | E39: OK | BE39: 0 | BF39: 23 | BG39: 23 | BI39: Thamires Ribeiro
A40: PRJ0010321 | B40: Programa-5S Estruturação TI | C40: ativo | E40: OK | BE40: 4 | BF40: 19 | BG40: 23 | BI40: Felipe Athar
A41: PRJ0010218 | B41: Migração SGA | C41: ativo | E41: OK | BE41: 5 | BF41: 18 | BG41: 23 | BI41: Thamires Ribeiro
...

Sheet BI
A1: Projetos Concluídos % | B1: Projetos cancelados % | C1: Projetos On Hold % | D1: A iniciar % | E1: Qtd de Projetos DG3 | F1: Ativos | G1: Projetos Concluídos | H1: Projetos cancelados | I1: Projetos On Hold | J1: A iniciar | K1: Status Enviados | L1: Consolidado Anual | M1: Semana 1 | N1: Semana 2 | O1: Semana 3 | P1: Semana 4 | Q1: Semana 5 | R1: Semana 6 | S1: Semana 7 | T1: Semana 8 | U1: Semana 9 | V1: Semana 10 | W1: Semana 11 | X1: Semana 12 | Y1: Semana 13 | Z1: Semana 14 | AA1: Semana 15 | AB1: Semana 16 | AC1: Semana 17 | AD1: Semana 18 | AE1: Semana 19 | AF1: Semana 20 | AG1: Semana 21 | AH1: Semana 22 | AI1: Semana 23 | AJ1: Semana 24 | AK1: Semana 25 | AL1: Semana 26 | AM1: Semana 27 | AN1: Semana 28 | AO1: Semana 29 | AP1: Semana 30 | AQ1: Semana 31 | AR1: Semana 32 | AS1: Semana 33 | AT1: Semana 34 | AU1: Semana 35 | AV1: Semana 36 | AW1: Semana 37 | AX1: Semana 38 | AY1: Semana 39 | AZ1: Semana 40 | BA1: Semana 41 | BB1: Semana 42 | BC1: Semana 43 | BD1: Semana 44 | BE1: Semana 45 | BF1: Semana 46 | BG1: Semana 47 | BH1: Semana 48 | BI1: Semana 49 | BJ1: Semana 50 | BK1: Semana 51 | BL1: Semana 52
A2: =G2/$E$2 -> 0.058823529 | B2: =H2/$E$2 -> 0.098039216 | C2: =I2/$E$2 -> 0.15686275 | D2: =J2/$E$2 -> 0.11764706 | E2: =COUNTA(StatusReport_2026_NovaFormula!B2:B55) -> 51 | F2: =COUNTIF(StatusReport_2026_NovaFormula!C1:C54,"ativo") -> 29 | G2: =COUNTIF(StatusReport_2026_NovaFormula!C2:C55,"concluído") -> 3 | H2: =COUNTIF(StatusReport_2026_NovaFormula!C2:C55,"cancelado") -> 5 | I2: =COUNTIF(StatusReport_2026_NovaFormula!C2:C55,"on hold") -> 8 | J2: =COUNTIF(StatusReport_2026_NovaFormula!C2:C55,"a iniciar") -> 6 | K2: =SUM(M7:AC7) -> 51 | L2: =AVERAGE(M2:AJ2) -> 0.073275862 | M2: =M7/$F$2 -> 1.7586207 | N2: =N7/$F$2 -> 0 | O2: =O7/$F$2 -> 0 | P2: =P7/$F$2 -> 0 | Q2: =Q7/$F$2 -> 0 | R2: =R7/$F$2 -> 0 | S2: =S7/$F$2 -> 0 | T2: =T7/$F$2 -> 0 | ... BL2: =BL7/$F$2 -> 0
M7: =COUNTA(StatusReport_2026_NovaFormula!E2:E67) -> 51 | N7: =COUNTA(StatusReport_2026_NovaFormula!F2:F67) -> 0 | O7: =COUNTA(StatusReport_2026_NovaFormula!G2:G67) -> 0 | P7: =COUNTA(StatusReport_2026_NovaFormula!H2:H67) -> 0 | Q7: =COUNTA(StatusReport_2026_NovaFormula!I2:I67) -> 0 | R7: =COUNTA(StatusReport_2026_NovaFormula!J2:J67) -> 0 | S7: =COUNTA(StatusReport_2026_NovaFormula!K2:K67) -> 0 | T7: =COUNTA(StatusReport_2026_NovaFormula!L2:L67) -> 0 | ... BL7: =COUNTA(StatusReport_2026_NovaFormula!BD2:BD67) -> 0

Sheet StatusReport_2026_backup
A1: Project ID | B1: Project Name | C1: Status Projeto | D1: Resposnável pelo Envio | E1: Semana 1 | F1: Semana 2 | G1: Semana 3 | H1: Semana 4 | I1: Semana 5 | J1: Semana 6 | K1: Semana 7 | L1: Semana 8 | M1: Semana 9 | N1: Semana 10 | O1: Semana 11 | P1: Semana 12 | Q1: Semana 13 | R1: Semana 14 | S1: Semana 15 | T1: Semana 16 | U1: Semana 17 | V1: Semana 18 | W1: Semana 19 | X1: Semana 20 | Y1: Semana 21 | Z1: Semana 22 | AA1: Semana 23 | AB1: Semana 24 | AC1: Semana 25 | AD1: Semana 26 | AE1: Semana 27 | AF1: Semana 28 | AG1: Semana 29 | AH1: Semana 30 | AI1: Semana 31 | AJ1: Semana 32 | AK1: Semana 33 | AL1: Semana 34 | AM1: Semana 35 | AN1: Semana 36 | AO1: Semana 37 | AP1: Semana 38 | AQ1: Semana 39 | AR1: Semana 40 | AS1: Semana 41 | AT1: Semana 42 | AU1: Semana 43 | AV1: Semana 44 | AW1: Semana 45 | AX1: Semana 46 | AY1: Semana 47 | AZ1: Semana 48 | BA1: Semana 49 | BB1: Semana 50 | BC1: Semana 51 | BD1: Semana 52 | BE1: Total de Status nas Semanas | BF1: Total de status não enviados | BG1: Total que deveria ter sido enviado | BH1: OBS | BI1: PM | BJ1: Detal. Resp. Envio
A2: PRJ-3736 | B2: ADN - Integração PI System x SysCAD _ 2025 | C2: ativo | D2: GBS IT PMO | Q2: ok | R2: ok | S2: ok | T2: ok | W2: ok | BE2: =COUNTA(E2:U2) -> 4 | BF2: =WEEKNUM(TODAY())-BE2 -> 20 | BG2: =BF2+BE2 -> 24 | BI2: Felipe Athar | BJ2: Vanessa dos Santos
A3: PRJ-3371 | B3: ADN24 - Migração do GPA para o ICS | C3: on hold | D3: julio.cesar.oliveira@hydro.com | BI3: Felipe Athar
A4: PRJ-3413 | B4: ADN - SGA - Fase 03 | C4: on hold | D4: PARCEIRO | Q4: ok | S4: ok | T4: ok | BE4: =COUNTA(E4:U4) -> 3 | BF4: =WEEKNUM(TODAY())-BE4 -> 21 | BG4: =BF4+BE4 -> 24 | BI4: Thamires Ribeiro | BJ4: RADIX
A5: PRJ-3509 | B5: ADN23 - SGE (Sistema de Gestão de Eventos) | C5: on hold | D5: PARCEIRO | O5: ok | Q5: ok | R5: ok | S5: ok | T5: ok | W5: ok | BE5: =COUNTA(E5:U5) -> 5 | BF5: =WEEKNUM(TODAY())-BE5 -> 19 | BG5: =BF5+BE5 -> 24 | BI5: Felipe Athar | BJ5: RADIX
A6: PRJ-2539 | B6: ADN24 - Migração PI System para o ICS - Fase 1 | C6: Concluído | D6: GBS IT PMO | BE6: =COUNTA(E6:U6) -> 0 | BF6: =WEEKNUM(TODAY())-BE6 -> 24 | BG6: =BF6+BE6 -> 24 | BI6: Felipe Athar
A7: PRJ-3829 | B7: ADN25 - FC02 FIBRA MINERODUTO | C7: a iniciar | D7: julio.cesar.oliveira@hydro.com | E7: ok | BE7: =COUNTA(E7:U7) -> 1 | BF7: =WEEKNUM(TODAY())-BE7 -> 23 | BG7: =BF7+BE7 -> 24 | BI7: Felipe Athar
A8: PRJ-3828 | B8: ADN25 - FC03 CONECTIVIDADE OPGW | C8: a iniciar | D8: GBS IT PMO | BE8: =COUNTA(E8:U8) -> 0 | BF8: =WEEKNUM(TODAY())-BE8 -> 24 | BG8: =BF8+BE8 -> 24 | BI8: Felipe Athar
A9: PRJ-2724 | B9: ADN25 - FC06 LTE | C9: a iniciar | D9: julio.cesar.oliveira@hydro.com | BE9: =COUNTA(E9:U9) -> 0 | BF9: =WEEKNUM(TODAY())-BE9 -> 24 | BG9: =BF9+BE9 -> 24 | BI9: Felipe Athar
A10: PRJ-3443 | B10: ADN25 - FC08 RÁDIO LINK | C10: a iniciar | D10: GBS IT PMO | BE10: =COUNTA(E10:U10) -> 0 | BF10: =WEEKNUM(TODAY())-BE10 -> 24 | BG10: =BF10+BE10 -> 24 | BI10: Felipe Athar
A11: PRJ-3372 | B11: ADN25 - Migração do PI System para o ICS - Fase 02 | C11: ativo | D11: PARCEIRO | K11: ok | O11: ok | P11: ok | Q11: ok | R11: ok | S11: ok | T11: ok | W11: ok | BE11: =COUNTA(E11:U11) -> 7 | BF11: =WEEKNUM(TODAY())-BE11 -> 17 | BG11: =BF11+BE11 -> 24 | BI11: Felipe Athar | BJ11: RADIX
A12: PRJ-3447 | B12: Expansion & Renovation Project | C12: ativo | D12: GBS IT PMO | BE12: =COUNTA(E12:U12) -> 0 | BF12: =WEEKNUM(TODAY())-BE12 -> 24 | BG12: =BF12+BE12 -> 24 | BI12: Felipe Athar
A13: PRJ-3756 | B13: HOC - Hydro Operations Center | C13: ativo | D13: julio.cesar.oliveira@hydro.com | F13: ok | G13: ok | H13: ok | I13: ok | M13: ok | N13: ok | P13: ok | Q13: ok | R13: ok | U13: ok | W13: ok | Y13: ok | BE13: =COUNTA(E13:U13) -> 10 | BF13: =WEEKNUM(TODAY())-BE13 -> 14 | BG13: =BF13+BE13 -> 24 | BI13: Felipe Athar
A14: PRJ-1478 | B14: ICS Config ICS and WLC | C14: ativo | D14: GBS IT PMO | E14: ok | H14: ok | K14: ok | L14: ok | N14: ok | R14: ok | BE14: =COUNTA(E14:U14) -> 6 | BF14: =WEEKNUM(TODAY())-BE14 -> 18 | BG14: =BF14+BE14 -> 24 | BI14: Felipe Athar
A15: PRJ-3448 | B15: Integração Starlink a WLAN controller | C15: ativo | D15: GBS IT PMO | BE15: =COUNTA(E15:U15) -> 0 | BF15: =WEEKNUM(TODAY())-BE15 -> 24 | BG15: =BF15+BE15 -> 24 | BI15: Felipe Athar
A16: PRJ-2758 | B16: PAM - Sistema de Monitoramento Proteção Catódica | C16: ativo | D16: GBS IT PMO | M16: ok | O16: ok | Q16: ok | R16: ok | S16: ok | T16: ok | BE16: =COUNTA(E16:U16) -> 6 | BF16: =WEEKNUM(TODAY())-BE16 -> 18 | BG16: =BF16+BE16 -> 24 | BI16: Thamires Ribeiro | BJ16: Vanessa dos Santos
A17: PRJ-2723 | B17: PAM22 - FC05 LTE | C17: ativo | D17: julio.cesar.oliveira@hydro.com | BE17: =COUNTA(E17:U17) -> 0 | BF17: =WEEKNUM(TODAY())-BE17 -> 24 | BG17: =BF17+BE17 -> 24 | BI17: Felipe Athar
A18: PRJ-1032 | B18: PAM22 - Fibra Mina Cidade | C18: ativo | D18: vinicius.costa.moraes@Hydro.com | E18: ok | F18: ok | G18: ok | H18: ok | I18: ok | J18: ok | K18: ok | L18: ok | M18: ok | N18: ok | O18: ok | P18: ok | Q18: ok | R18: ok | S18: ok | T18: ok | U18: ok | V18: ok | W18: ok | X18: ok | Y18: ok | BE18: =COUNTA(E18:U18) -> 17 | BF18: =WEEKNUM(TODAY())-BE18 -> 7 | BG18: =BF18+BE18 -> 24 | BI18: Felipe Athar
A19: PRJ-3414 | B19: PAM22 - Monitoramento das Torres de Transmissão de Energia via Satélite | C19: ativo | D19: GBS IT PMO | O19: ok | Q19: ok | R19: ok | S19: ok | T19: ok | BE19: =COUNTA(E19:U19) -> 5 | BF19: =WEEKNUM(TODAY())-BE19 -> 19 | BG19: =BF19+BE19 -> 24 | BI19: Thamires Ribeiro | BJ19: Vanessa dos Santos
A20: PRJ-2572 | B20: PAM24 - Ampliação da cobertura do sinal de telefonia móvel | C20: ativo | D20: GBS IT PMO | BE20: =COUNTA(E20:U20) -> 0 | BF20: =WEEKNUM(TODAY())-BE20 -> 24 | BG20: =BF20+BE20 -> 24 | BI20: Felipe Athar
A21: PRJ-2767 | B21: PAM24 - Gestão de Parads de Ativos | C21: ativo | D21: GBS IT PMO | S21: ok | T21: ok | BE21: =COUNTA(E21:U21) -> 2 | BF21: =WEEKNUM(TODAY())-BE21 -> 22 | BG21: =BF21+BE21 -> 24 | BI21: Thamires Ribeiro
A22: PRJ-2905 | B22: PAM24 - M5 - Corporate Networking | C22: on hold | D22: GBS IT PMO | BE22: =COUNTA(E22:U22) -> 0 | BF22: =WEEKNUM(TODAY())-BE22 -> 24 | BG22: =BF22+BE22 -> 24 | BI22: Thamires Ribeiro
A23: PRJ-2911 | B23: PAM24 - M5 - Remote Station | C23: ativo | D23: julio.cesar.oliveira@hydro.com | V23: ok | Y23: ok | BE23: =COUNTA(E23:U23) -> 0 | BF23: =WEEKNUM(TODAY())-BE23 -> 24 | BG23: =BF23+BE23 -> 24 | BI23: Thamires Ribeiro
A24: PRJ-2958 | B24: PAM24 Topography Backup | C24: on hold | D24: GBS IT PMO | BE24: =COUNTA(E24:U24) -> 0 | BF24: =WEEKNUM(TODAY())-BE24 -> 24 | BG24: =BF24+BE24 -> 24 | BI24: Felipe Athar
A25: PRJ-3821 | B25: PAM25 - Embuchamento dos Moinhos | C25: a iniciar | D25: GBS IT PMO | BE25: =COUNTA(E25:U25) -> 0 | BF25: =WEEKNUM(TODAY())-BE25 -> 24 | BG25: =BF25+BE25 -> 24 | BI25: Thamires Ribeiro
A26: PRJ-3815 | B26: PAM25 - GEOTEC - Otimização de Disposição dos Rejeitos | C26: ativo | D26: GBS IT PMO | G26: ok | H26: ok | J26: ok | L26: ok | M26: ok | O26: OK | P26: OK | Q26: ok | R26: ok | S26: ok | T26: ok | BE26: =COUNTA(E26:U26) -> 11 | BF26: =WEEKNUM(TODAY())-BE26 -> 13 | BG26: =BF26+BE26 -> 24 | BI26: Thamires Ribeiro | BJ26: Vanessa dos Santos
A27: PRJ-2756 | B27: PAM25 - GEOTEC - Projeto Integração da Rede de Geotecnia | C27: Ativo | D27: julio.cesar.oliveira@hydro.com | G27: ok | H27: ok | J27: ok | Q27: ok | R27: ok | S27: ok | T27: ok | W27: ok | X27: ok | BE27: =COUNTA(E27:U27) -> 7 | BF27: =WEEKNUM(TODAY())-BE27 -> 17 | BG27: =BF27+BE27 -> 24 | BI27: Thamires Ribeiro | BJ27: Vanessa dos Santos
A28: PRJ-3691 | B28: PAM25 - GEOTEC - Verificação de Anomalias nas Barragens por IA | C28: ativo | D28: julio.cesar.oliveira@hydro.com | G28: ok | H28: ok | J28: ok | L28: ok | M28: ok | O28: OK | P28: OK | R28: ok | S28: ok | T28: ok | BE28: =COUNTA(E28:U28) -> 10 | BF28: =WEEKNUM(TODAY())-BE28 -> 14 | BG28: =BF28+BE28 -> 24 | BI28: Thamires Ribeiro | BJ28: Vanessa dos Santos
A29: PRJ-3468 | B29: PAM25 - GEOTEC - Visibilidade noturna na barragem | C29: ativo | D29: GBS IT PMO | G29: ok | H29: ok | J29: ok | L29: ok | M29: ok | O29: OK | P29: OK | R29: ok | S29: ok | T29: ok | BE29: =COUNTA(E29:U29) -> 10 | BF29: =WEEKNUM(TODAY())-BE29 -> 14 | BG29: =BF29+BE29 -> 24 | BI29: Thamires Ribeiro | BJ29: Vanessa dos Santos
B30: PAM25 - GEOTEC - Monitoramento ZAS | C30: ativo | D30: GBS IT PMO | J30: ok | L30: ok | M30: ok | O30: OK | P30: OK | R30: ok | S30: ok | T30: ok | BF30: =WEEKNUM(TODAY())-BE30 -> 24 | BI30: Thamires Ribeiro | BJ30: Vanessa dos Santos
A31: PRJ-3563 | B31: PAM25 - Migração dos Servidores do Despacho | C31: ativo | D31: GBS IT PMO | J31: ok | K31: ok | M31: ok | O31: ok | R31: ok | S31: ok | T31: ok | U31: ok | V31: ok | W31: ok | X31: ok | Y31: ok | BE31: =COUNTA(E31:U31) -> 8 | BF31: =WEEKNUM(TODAY())-BE31 -> 16 | BG31: =BF31+BE31 -> 24 | BI31: Thamires Ribeiro
A32: PRJ-3441 | B32: PAM25 - Process Optimization - Quality improvement of mining product - Advanced control | C32: on hold | D32: GBS IT PMO | BE32: =COUNTA(E32:U32) -> 0 | BF32: =WEEKNUM(TODAY())-BE32 -> 24 | BG32: =BF32+BE32 -> 24 | BI32: Thamires Ribeiro | BJ32: Vanessa dos Santos
A33: PRJ-3786 | B33: PAM25 - Processo de Otimização do Consumo de Floculante | C33: on hold | D33: GBS IT PMO | I33: ok | J33: ok | M33: ok | N33: ok | S33: ok | BE33: =COUNTA(E33:U33)/2 -> 2.5 | BF33: =WEEKNUM(TODAY())-BE33 -> 21.5 | BG33: =BF33+BE33 -> 24 | BI33: Thamires Ribeiro
A34: PRJ-3446 | B34: PAM25 FPS02_Governança PI System - Fase I | C34: On hold | D34: PARCEIRO | F34: 3 | O34: ok | Q34: ok | R34: ok | S34: ok | T34: ok | BE34: =COUNTA(E34:U34) -> 6 | BF34: =WEEKNUM(TODAY())-BE34 -> 18 | BG34: =BF34+BE34 -> 24 | BI34: Felipe Athar
A35: PRJ-3720 | B35: PAM25_PO01_Controle_Regulatorio_Ciclonagem | C35: ativo | D35: PARCEIRO | F35: ok | J35: ok | K35: ok | L35: ok | M35: ok | P35: OK | BE35: =COUNTA(E35:U35) -> 6 | BF35: =WEEKNUM(TODAY())-BE35 -> 18 | BG35: =BF35+BE35 -> 24 | BI35: Thamires Ribeiro | BJ35: RADIX
A36: PRJ-1040 | B36: PAM26 - Ampliação do Sistema de CFTV da MPSA | C36: ativo | D36: julio.cesar.oliveira@hydro.com | F36: ok | G36: ok | H36: ok | I36: ok | J36: ok | K36: ok | M36: ok | N36: ok | P36: ok | Q36: ok | R36: ok | S36: ok | BE36: =COUNTA(E36:U36) -> 12 | BF36: =WEEKNUM(TODAY())-BE36 -> 12 | BG36: =BF36+BE36 -> 24 | BI36: Thamires Ribeiro | BJ36: IHM
A37: PRJ-2811 | B37: PAM26 - Câmeras Corporais | C37: a iniciar | D37: GBS IT PMO | Y37: ok | BE37: =COUNTA(E37:U37) -> 0 | BF37: =WEEKNUM(TODAY())-BE37 -> 24 | BG37: =BF37+BE37 -> 24 | BI37: Thamires Ribeiro
A38: PRJ-3876 | B38: PoC AVEVA Mobile Operator | C38: on hold | D38: julio.cesar.oliveira@hydro.com | BE38: =COUNTA(E38:U38) -> 0 | BF38: =WEEKNUM(TODAY())-BE38 -> 24 | BG38: =BF38+BE38 -> 24 | BI38: Thamires Ribeiro
A39: PRJ-3877 | B39: Programa Ecoar | C39: ativo | D39: GBS IT PMO | BE39: =COUNTA(E39:U39) -> 0 | BF39: =WEEKNUM(TODAY())-BE39 -> 24 | BG39: =BF39+BE39 -> 24 | BI39: Thamires Ribeiro
A40: PRJ-3722 | B40: Programa-5S_Estruturacao dos Almoxarifados de T I_ 2025 | C40: ativo | D40: GBS IT PMO | Q40: ok | R40: ok | S40: ok | T40: ok | W40: ok | BE40: =COUNTA(E40:U40) -> 4 | BF40: =WEEKNUM(TODAY())-BE40 -> 20 | BG40: =BF40+BE40 -> 24 | BI40: Felipe Athar | BJ40: Vanessa dos Santos
...
